Workbook

Sheet Notes
A1: Source & Modeling Notes
A3: Company | B3: Hawkins Cookers Limited
A4: Reporting periods | B4: FY2021 through FY2026
A5: Scope | B5: Standalone financial statements
A6: Units | B6: Rs. Lakhs, as reported in Hawkins annual reports
A7: Historical data | B7: Hardcoded reported historical figures; no forecasts.
A8: FY2021-FY2022 source | B8: Hawkins Annual Report 2021-22, Balance Sheet p.38, Profit & Loss p.39, Cash Flow p.41.
A9: FY2023-FY2024 source | B9: Hawkins Annual Report 2023-24, Balance Sheet p.50, Profit & Loss p.51, Cash Flow p.53.
A10: FY2025-FY2026 source | B10: Hawkins Annual Report 2025-26, Balance Sheet p.30, Profit & Loss p.31, Cash Flow p.33.
A11: Nil treatment | B11: Explicit NIL figures are represented as numeric 0.00 where required for model usability. Blank cells are not used to fabricate values.
A12: Formatting | B12: M&M Income Statement formatting is used as the visual master: colours, borders/lines, fonts, text hierarchy, spacing and number presentation.
A13: Purpose | B13: Historical financial statement database suitable for ratio analysis, assumptions/drivers and three-statement financial modelling.
A16: DATA SHEETS | B16: Historical annual report data sheets (Do Not Change value) but can add Years and values from new Reports
A17: MODELS | B17: Financial Modeling Sheets (Analysis) - Depended on DATA SHEETS

Sheet One Page Profile
B2: One Page Profile - Hawkins Cookers Limited
C4: ='OPP Data'!C2 -> Hawkins Cookers Limited Inc and formerly known as Pressure Cookers and Appliances Ltd, is an Indian company which manufactures pressure cookers and cookware. The company is based in Mumbai and has three manufacturing plants at Thane, Hoshiarpur and Jaunpur. It manufactures under brand names of Hawkins, Futura, Contura, Hevibase, Big Boy, Miss Mary and Ventura. Hawkins is one of the largest pressure cooker manufacturers in India and exports its products to more than 65 countries.
B5: (Values in Rs. Lakhs)
B6: Key Finacial Metrics | C6: 2022 | D6: 2023 | E6: 2024 | F6: 2025 | G6: 2026 | I6: Share Price - 5 Yr
B8: Total Revenue | C8: =HistoricalFS!D9 -> 95801.19 | D8: =HistoricalFS!E9 -> 100579.5 | E8: =HistoricalFS!F9 -> 102414.97 | F8: =HistoricalFS!G9 -> 111575.66 | G8: =HistoricalFS!H9 -> 125292.73
B9: Revenue Growth YoY | C9: =HistoricalFS!D10 -> 0.2466656 | D9: =HistoricalFS!E10 -> 0.049877355 | E9: =HistoricalFS!F10 -> 0.018248947 | F9: =HistoricalFS!G10 -> 0.089446787 | G9: =HistoricalFS!H10 -> 0.12293963
B10: Gross Profit Margins (%) | C10: =HistoricalFS!D13 -> 0.51024742 | D10: =HistoricalFS!E13 -> 0.50845152 | E10: =HistoricalFS!F13 -> 0.48137055 | F10: =HistoricalFS!G13 -> 0.4810197 | G10: =HistoricalFS!H13 -> 0.49207963
B11: EBITDA Margins (%) | C11: =HistoricalFS!D22 -> 0.12500815 | D11: =HistoricalFS!E22 -> 0.13455396 | E11: =HistoricalFS!F22 -> 0.14665786 | F11: =HistoricalFS!G22 -> 0.1385061 | G11: =HistoricalFS!H22 -> 0.1442723
B12: EBIT Margins (%) | C12: ='Ratio Analysis'!D17 -> 0.11805929 | D12: ='Ratio Analysis'!E17 -> 0.12687884 | E12: ='Ratio Analysis'!F17 -> 0.13817873 | F12: ='Ratio Analysis'!G17 -> 0.12928223 | G12: ='Ratio Analysis'!H17 -> 0.13342083
B13: Net Profit Margins (%) | C13: =HistoricalFS!D40 -> 0.087562795 | D13: =HistoricalFS!E40 -> 0.094231131 | E13: =HistoricalFS!F40 -> 0.10724585 | F13: =HistoricalFS!G40 -> 0.10279366 | G13: =HistoricalFS!H40 -> 0.10470544
B14: Earnings Per Share (in Rs) | C14: =HistoricalFS!D44 -> 158.64057 | D14: =HistoricalFS!E44 -> 179.23698 | E14: =HistoricalFS!F44 -> 207.71491 | F14: =HistoricalFS!G44 -> 216.89999 | G14: =HistoricalFS!H44 -> 248.09548
B15: EPS Growth YoY | C15: =HistoricalFS!D45 -> 0.040310929 | D15: =HistoricalFS!E45 -> 0.12983065 | E15: =HistoricalFS!F45 -> 0.1588842 | F15: =HistoricalFS!G45 -> 0.044219644 | G15: =HistoricalFS!H45 -> 0.14382432
B16: Dividend Per Share (in Rs.) | C16: =HistoricalFS!D47 -> 90.350551 | D16: =HistoricalFS!E47 -> 60.679127 | E16: =HistoricalFS!F47 -> 100.68488 | F16: =HistoricalFS!G47 -> 120.22546 | G16: =HistoricalFS!H47 -> 130.00001
B17: Dividend Growth YoY | C17: =(HistoricalFS!D47/HistoricalFS!C47)-1 -> 0.12624085 | D17: =(HistoricalFS!E47/HistoricalFS!D47)-1 -> -0.32840335 | E17: =(HistoricalFS!F47/HistoricalFS!E47)-1 -> 0.65930001 | F17: =(HistoricalFS!G47/HistoricalFS!F47)-1 -> 0.19407667 | G17: =(HistoricalFS!H47/HistoricalFS!G47)-1 -> 0.081301811
B19: Key Finacial Ratios | C19: 2022 | D19: 2023 | E19: 2024 | F19: 2025 | G19: 2026
B21: Price to Earnings
B22: EV/EBITDA
B23: EV/Revenue
B24: Price to Book Value
B25: Return on Equity (%) | C25: ='Ratio Analysis'!D27 -> 0.39349976 | D25: ='Ratio Analysis'!E27 -> 0.34323361 | E25: ='Ratio Analysis'!F27 -> 0.32936228 | F25: ='Ratio Analysis'!G27 -> 0.29926731 | G25: ='Ratio Analysis'!H27 -> 0.29464235
B26: Return on Capital Employed (%) | C26: ='Ratio Analysis'!D25 -> 0.48056118 | D26: ='Ratio Analysis'!E25 -> 0.44382341 | E26: ='Ratio Analysis'!F25 -> 0.43838235 | F26: ='Ratio Analysis'!G25 -> 0.39493441 | G26: ='Ratio Analysis'!H25 -> 0.38685906

Sheet OPP Data
B2: Dsescription | C2: Hawkins Cookers Limited Inc and formerly known as Pressure Cookers and Appliances Ltd, is an Indian company which manufactures pressure cookers and cookware. The company is based in Mumbai and has three manufacturing plants at Thane, Hoshiarpur and Jaunpur. It manufactures under brand names of Hawkins, Futura, Contura, Hevibase, Big Boy, Miss Mary and Ventura. Hawkins is one of the largest pressure cooker manufacturers in India and exports its products to more than 65 countries.
E3: Date | F3: Adj Close | P3: Date | Q3: Adj Close
E4: 46135 | F4: 7452.9468 | P4: 44446 | Q4: 5762.7075
E5: 46136 | F5: 7357.8223 | P5: 44447 | Q5: 5746.4204
E6: 46139 | F6: 7381.1729 | P6: 44448 | Q6: 5784.2676
E7: 46140 | F7: 7362.6655 | P7: 44452 | Q7: 5809.4688
E8: 46141 | F8: 7357.7139 | P8: 44453 | Q8: 5792.1553
E9: 46142 | F9: 7343.7842 | P9: 44454 | Q9: 5854.083
E10: 46146 | F10: 7293.5693 | P10: 44455 | Q10: 5844.6562
E11: 46147 | F11: 7247.3013 | P11: 44456 | Q11: 5787.7217
E12: 46148 | F12: 7241.395 | P12: 44459 | Q12: 5775.6816
E13: 46149 | F13: 7301.4443 | P13: 44460 | Q13: 5800.3687
E14: 46150 | F14: 7377.7368 | P14: 44461 | Q14: 5773.3008
E15: 46153 | F15: 7230.5664 | P15: 44462 | Q15: 5790.4751
... E100: 46272 | F100: 8254 | P100: 44586 | Q100: 5409.4341
P101: 44588 | Q101: 5491.9888
P102: 44589 | Q102: 5469.915
P103: 44592 | Q103: 5562.4565
P104: 44593 | Q104: 5544.6294
P105: 44594 | Q105: 5456.9409
P106: 44595 | Q106: 5405.9341
P107: 44596 | Q107: 5324.9185
P108: 44599 | Q108: 5299.7646
P109: 44600 | Q109: 5256.8774
P110: 44601 | Q110: 5296.7778
P111: 44602 | Q111: 5276.4775
P112: 44603 | Q112: 5223.6035
... P1238: 46269 | Q1238: 8413.3496

Sheet HistoricalFS
B2: Hawkins Cookers Limited
G4: (Values in Rs. Lakhs)
B6: Historical Financials - Hawkins Cookers Limited
B7: Years | C7: 2021 | D7: =C7+1 -> 2022 | E7: =D7+1 -> 2023 | F7: =E7+1 -> 2024 | G7: =F7+1 -> 2025 | H7: =G7+1 -> 2026
A8: # | B8: Income Statement
B9: Revenue from operations | C9: =IFERROR('Income Statement'!B5,0) -> 76845.94 | D9: =IFERROR('Income Statement'!C5,0) -> 95801.19 | E9: =IFERROR('Income Statement'!D5,0) -> 100579.5 | F9: =IFERROR('Income Statement'!E5,0) -> 102414.97 | G9: =IFERROR('Income Statement'!F5,0) -> 111575.66 | H9: =IFERROR('Income Statement'!G5,0) -> 125292.73
B10: Revenue Growth % | D10: =IFERROR(D9/C9-1,0) -> 0.2466656 | E10: =IFERROR(E9/D9-1,0) -> 0.049877355 | F10: =IFERROR(F9/E9-1,0) -> 0.018248947 | G10: =IFERROR(G9/F9-1,0) -> 0.089446787 | H10: =IFERROR(H9/G9-1,0) -> 0.12293963
B12: Cost of Goods Sold | C12: =IFERROR(SUM('Income Statement'!B9:B11),0) -> 36519.71 | D12: =IFERROR(SUM('Income Statement'!C9:C11),0) -> 48882.31 | E12: =IFERROR(SUM('Income Statement'!D9:D11),0) -> 51139.8 | F12: =IFERROR(SUM('Income Statement'!E9:E11),0) -> 49299.55 | G12: =IFERROR(SUM('Income Statement'!F9:F11),0) -> 53670.09 | H12: =IFERROR(SUM('Income Statement'!G9:G11),0) -> 61654
B13: COGS % Revenue | C13: =C12/C9 -> 0.47523278 | D13: =D12/D9 -> 0.51024742 | E13: =E12/E9 -> 0.50845152 | F13: =F12/F9 -> 0.48137055 | G13: =G12/G9 -> 0.4810197 | H13: =H12/H9 -> 0.49207963
B15: Gross Profit | C15: =IFERROR(C9-C12,0) -> 40326.23 | D15: =IFERROR(D9-D12,0) -> 46918.88 | E15: =IFERROR(E9-E12,0) -> 49439.7 | F15: =IFERROR(F9-F12,0) -> 53115.42 | G15: =IFERROR(G9-G12,0) -> 57905.57 | H15: =IFERROR(H9-H12,0) -> 63638.73
B16: Gross Profit Margin % | C16: =C15/C9 -> 0.52476722 | D16: =D15/D9 -> 0.48975258 | E16: =E15/E9 -> 0.49154848 | F16: =F15/F9 -> 0.51862945 | G16: =G15/G9 -> 0.5189803 | H16: =H15/H9 -> 0.50792037
B18: Selling & General Expenses | C18: =IFERROR(SUM('Income Statement'!B12,'Income Statement'!B15),0) -> 29245.31 | D18: =IFERROR(SUM('Income Statement'!C12,'Income Statement'!C15),0) -> 34942.95 | E18: =IFERROR(SUM('Income Statement'!D12,'Income Statement'!D15),0) -> 35906.33 | F18: =IFERROR(SUM('Income Statement'!E12,'Income Statement'!E15),0) -> 38095.46 | G18: =IFERROR(SUM('Income Statement'!F12,'Income Statement'!F15),0) -> 42451.66 | H18: =IFERROR(SUM('Income Statement'!G12,'Income Statement'!G15),0) -> 45562.46
B19: SG&A % Revenue | C19: =C18/C9 -> 0.38057066 | D19: =D18/D9 -> 0.36474443 | E19: =E18/E9 -> 0.35699452 | F19: =F18/F9 -> 0.3719716 | G19: =G18/G9 -> 0.3804742 | H19: =H18/H9 -> 0.36364807
B21: EBITDA | C21: =IFERROR(C15-C18,0) -> 11080.92 | D21: =IFERROR(D15-D18,0) -> 11975.93 | E21: =IFERROR(E15-E18,0) -> 13533.37 | F21: =IFERROR(F15-F18,0) -> 15019.96 | G21: =IFERROR(G15-G18,0) -> 15453.91 | H21: =IFERROR(H15-H18,0) -> 18076.27
B22: EBITDA Margin | C22: =C21/C9 -> 0.14419656 | D22: =D21/D9 -> 0.12500815 | E22: =E21/E9 -> 0.13455396 | F22: =F21/F9 -> 0.14665786 | G22: =G21/G9 -> 0.1385061 | H22: =H21/H9 -> 0.1442723
B24: Finance costs | C24: =IFERROR('Income Statement'!B13,0) -> 473.48 | D24: =IFERROR('Income Statement'!C13,0) -> 605.71 | E24: =IFERROR('Income Statement'!D13,0) -> 486.31 | F24: =IFERROR('Income Statement'!E13,0) -> 455.02 | G24: =IFERROR('Income Statement'!F13,0) -> 290.31 | H24: =IFERROR('Income Statement'!G13,0) -> 352.88
B25: Finance costs % Revenue | C25: =C24/C9 -> 0.0061614185 | D25: =D24/D9 -> 0.0063225728 | E25: =E24/E9 -> 0.0048350807 | F25: =F24/F9 -> 0.0044429052 | G25: =G24/G9 -> 0.0026019116 | H25: =H24/H9 -> 0.0028164443
B27: Depreciation and Amortization | C27: =IFERROR('Income Statement'!B14,0) -> 533.14 | D27: =IFERROR('Income Statement'!C14,0) -> 665.71 | E27: =IFERROR('Income Statement'!D14,0) -> 771.96 | F27: =IFERROR('Income Statement'!E14,0) -> 868.39 | G27: =IFERROR('Income Statement'!F14,0) -> 1029.16 | H27: =IFERROR('Income Statement'!G14,0) -> 1359.61
B28: D&A % Revenue | C28: =C27/C9 -> 0.0069377771 | D28: =D27/D9 -> 0.0069488698 | E28: =E27/E9 -> 0.0076751227 | F28: =F27/F9 -> 0.0084791315 | G28: =G27/G9 -> 0.0092238755 | H28: =H27/H9 -> 0.010851468
B30: Other Income | C30: =IFERROR('Income Statement'!B6,0) -> 731.98 | D30: =IFERROR('Income Statement'!C6,0) -> 586.12 | E30: =IFERROR('Income Statement'!D6,0) -> 416 | F30: =IFERROR('Income Statement'!E6,0) -> 1058.36 | G30: =IFERROR('Income Statement'!F6,0) -> 1352.86 | H30: =IFERROR('Income Statement'!G6,0) -> 1297.9
B31: Other Income % Revenue | C31: =C30/C9 -> 0.0095252918 | D31: =D30/D9 -> 0.0061180868 | E31: =E30/E9 -> 0.0041360317 | F31: =F30/F9 -> 0.010334036 | G31: =G30/G9 -> 0.012125046 | H31: =H30/H9 -> 0.010358941
B33: Earnings before Tax (EBT) | C33: =C21-SUM(C27,C24)+C30 -> 10806.28 | D33: =D21-SUM(D27,D24)+D30 -> 11290.63 | E33: =E21-SUM(E27,E24)+E30 -> 12691.1 | F33: =F21-SUM(F27,F24)+F30 -> 14754.91 | G33: =G21-SUM(G27,G24)+G30 -> 15487.3 | H33: =H21-SUM(H27,H24)+H30 -> 17661.68
B34: EBT Margins | C34: =C33/C9 -> 0.14062265 | D34: =D33/D9 -> 0.1178548 | E34: =E33/E9 -> 0.12617979 | F34: =F33/F9 -> 0.14406986 | G34: =G33/G9 -> 0.13880536 | H34: =H33/H9 -> 0.14096333
B36: Tax | C36: =IFERROR(SUM('Income Statement'!B19:B20),0) -> 2742.71 | D36: =IFERROR(SUM('Income Statement'!C19:C20),0) -> 2902.01 | E36: =IFERROR(SUM('Income Statement'!D19:D20),0) -> 3213.38 | F36: =IFERROR(SUM('Income Statement'!E19:E20),0) -> 3771.33 | G36: =IFERROR(SUM('Income Statement'!F19:F20),0) -> 4018.03 | H36: =IFERROR(SUM('Income Statement'!G19:G20),0) -> 4542.85
B37: Effective Tax Rate | C37: =C36/C33 -> 0.25380705 | D37: =D36/D33 -> 0.25702817 | E37: =E36/E33 -> 0.25319949 | F37: =F36/F33 -> 0.25559831 | G37: =G36/G33 -> 0.25944032 | H37: =H36/H33 -> 0.25721506
B39: Net Profit | C39: =C33-C36 -> 8063.57 | D39: =D33-D36 -> 8388.62 | E39: =E33-E36 -> 9477.72 | F39: =F33-F36 -> 10983.58 | G39: =G33-G36 -> 11469.27 | H39: =H33-H36 -> 13118.83
B40: Net Margins | C40: =C39/C9 -> 0.10493163 | D40: =D39/D9 -> 0.087562795 | E40: =E39/E9 -> 0.094231131 | F40: =F39/F9 -> 0.10724585 | G40: =G39/G9 -> 0.10279366 | H40: =H39/H9 -> 0.10470544
B42: No. of Equity Shares (in lakhs) | C42: =5287815/100000 -> 52.87815 | D42: =5287815/100000 -> 52.87815 | E42: =5287815/100000 -> 52.87815 | F42: =5287815/100000 -> 52.87815 | G42: =5287815/100000 -> 52.87815 | H42: =5287815/100000 -> 52.87815
B44: Earnings Per Share | C44: =IFERROR(C39/C42,0) -> 152.49342 | D44: =IFERROR(D39/D42,0) -> 158.64057 | E44: =IFERROR(E39/E42,0) -> 179.23698 | F44: =IFERROR(F39/F42,0) -> 207.71491 | G44: =IFERROR(G39/G42,0) -> 216.89999 | H44: =IFERROR(H39/H42,0) -> 248.09548
B45: EPS Growth | D45: =IFERROR(D44/C44-1,0) -> 0.040310929 | E45: =IFERROR(E44/D44-1,0) -> 0.12983065 | F45: =IFERROR(F44/E44-1,0) -> 0.1588842 | G45: =IFERROR(G44/F44-1,0) -> 0.044219644 | H45: =IFERROR(H44/G44-1,0) -> 0.14382432
B47: Dividend Per Share | C47: =IFERROR((('Cash Flow'!B40*-1)/HistoricalFS!C42),0) -> 80.223117 | D47: =IFERROR((('Cash Flow'!C40*-1)/HistoricalFS!D42),0) -> 90.350551 | E47: =IFERROR((('Cash Flow'!D40*-1)/HistoricalFS!E42),0) -> 60.679127 | F47: =IFERROR((('Cash Flow'!E40*-1)/HistoricalFS!F42),0) -> 100.68488 | G47: =IFERROR((('Cash Flow'!F40*-1)/HistoricalFS!G42),0) -> 120.22546 | H47: =IFERROR((('Cash Flow'!G40*-1)/HistoricalFS!H42),0) -> 130.00001
B48: Dividend Payout Ratio | C48: =C47/C44 -> 0.52607592 | D48: =D47/D44 -> 0.56952991 | E48: =E47/E44 -> 0.33854134 | F48: =F47/F44 -> 0.48472629 | G48: =G47/G44 -> 0.55428985 | H48: =H47/H44 -> 0.52399185
B50: Retained Earnings | C50: =IFERROR(1-C48,0) -> 0.47392408 | D50: =IFERROR(1-D48,0) -> 0.43047009 | E50: =IFERROR(1-E48,0) -> 0.66145866 | F50: =IFERROR(1-F48,0) -> 0.51527371 | G50: =IFERROR(1-G48,0) -> 0.44571015 | H50: =IFERROR(1-H48,0) -> 0.47600815
A52: # | B52: Balance Sheet
B53: NON-CURRENT ASSETS
B54: Property, Plant and Equipment | C54: =IFERROR('Balance Sheet'!B7,0) -> 3891.85 | D54: =IFERROR('Balance Sheet'!C7,0) -> 5162.06 | E54: =IFERROR('Balance Sheet'!D7,0) -> 6601.99 | F54: =IFERROR('Balance Sheet'!E7,0) -> 7195.46 | G54: =IFERROR('Balance Sheet'!F7,0) -> 8432.04 | H54: =IFERROR('Balance Sheet'!G7,0) -> 11997.55
B55: Capital Work-in-Progress | C55: =IFERROR('Balance Sheet'!B8,0) -> 277.98 | D55: =IFERROR('Balance Sheet'!C8,0) -> 323.11 | E55: =IFERROR('Balance Sheet'!D8,0) -> 215.95 | F55: =IFERROR('Balance Sheet'!E8,0) -> 1188.22 | G55: =IFERROR('Balance Sheet'!F8,0) -> 2245.13 | H55: =IFERROR('Balance Sheet'!G8,0) -> 1194.98
B56: Intangible assets | C56: =IFERROR('Balance Sheet'!B9,0) -> 9.49 | D56: =IFERROR('Balance Sheet'!C9,0) -> 17.19 | E56: =IFERROR('Balance Sheet'!D9,0) -> 15.28 | F56: =IFERROR('Balance Sheet'!E9,0) -> 11.87 | G56: =IFERROR('Balance Sheet'!F9,0) -> 45.98 | H56: =IFERROR('Balance Sheet'!G9,0) -> 68.94
B57: Investments | C57: =IFERROR('Balance Sheet'!B11,0) -> 0.25 | D57: =IFERROR('Balance Sheet'!C11,0) -> 0.25 | E57: =IFERROR('Balance Sheet'!D11,0) -> 0.25 | F57: =IFERROR('Balance Sheet'!E11,0) -> 0.25 | G57: =IFERROR('Balance Sheet'!F11,0) -> 0.25 | H57: =IFERROR('Balance Sheet'!G11,0) -> 0.25
B58: Other non-current financial assets | C58: =IFERROR('Balance Sheet'!B12,0) -> 1109.62 | D58: =IFERROR('Balance Sheet'!C12,0) -> 130.47 | E58: =IFERROR('Balance Sheet'!D12,0) -> 779.34 | F58: =IFERROR('Balance Sheet'!E12,0) -> 445.84 | G58: =IFERROR('Balance Sheet'!F12,0) -> 936.04 | H58: =IFERROR('Balance Sheet'!G12,0) -> 543.14
...

Sheet Ratio Analysis
B2: Hawkins Cookers Limited
J4: (Values in Rs. Lakhs)
B6: Ratio Analysis - Hawkins Cookers Limited
B7: Years | C7: 2021 | D7: =C7+1 -> 2022 | E7: =D7+1 -> 2023 | F7: =E7+1 -> 2024 | G7: =F7+1 -> 2025 | H7: =G7+1 -> 2026 | I7: Trend | J7: Mean | K7: Median
B9: Revenue Growth | D9: =IFERROR(HistoricalFS!D10,0) -> 0.2466656 | E9: =IFERROR(HistoricalFS!E10,0) -> 0.049877355 | F9: =IFERROR(HistoricalFS!F10,0) -> 0.018248947 | G9: =IFERROR(HistoricalFS!G10,0) -> 0.089446787 | H9: =IFERROR(HistoricalFS!H10,0) -> 0.12293963 | J9: =AVERAGE(D9:H9) -> 0.10543566 | K9: =MEDIAN(D9:H9) -> 0.089446787
B10: EBITDA Growth | D10: =IFERROR((HistoricalFS!D21/HistoricalFS!C21-1),0) -> 0.080770369 | E10: =IFERROR((HistoricalFS!E21/HistoricalFS!D21-1),0) -> 0.13004752 | F10: =IFERROR((HistoricalFS!F21/HistoricalFS!E21-1),0) -> 0.10984625 | G10: =IFERROR((HistoricalFS!G21/HistoricalFS!F21-1),0) -> 0.028891555 | H10: =IFERROR((HistoricalFS!H21/HistoricalFS!G21-1),0) -> 0.16968909 | J10: =AVERAGE(D10:H10) -> 0.10384896 | K10: =MEDIAN(D10:H10) -> 0.10984625
B11: EBIT Growth | D11: =IFERROR((HistoricalFS!D21-HistoricalFS!D27)/(HistoricalFS!C21-HistoricalFS!C27)-1,0) -> 0.072284405 | E11: =IFERROR((HistoricalFS!E21-HistoricalFS!E27)/(HistoricalFS!D21-HistoricalFS!D27)-1,0) -> 0.12830785 | F11: =IFERROR((HistoricalFS!F21-HistoricalFS!F27)/(HistoricalFS!E21-HistoricalFS!E27)-1,0) -> 0.10893467 | G11: =IFERROR((HistoricalFS!G21-HistoricalFS!G27)/(HistoricalFS!F21-HistoricalFS!F27)-1,0) -> 0.019303865 | H11: =IFERROR((HistoricalFS!H21-HistoricalFS!H27)/(HistoricalFS!G21-HistoricalFS!G27)-1,0) -> 0.15888733 | J11: =AVERAGE(D11:H11) -> 0.097543624 | K11: =MEDIAN(D11:H11) -> 0.10893467
B12: Net Profit Growth | D12: =IFERROR(HistoricalFS!D39/HistoricalFS!C39-1,0) -> 0.040310929 | E12: =IFERROR(HistoricalFS!E39/HistoricalFS!D39-1,0) -> 0.12983065 | F12: =IFERROR(HistoricalFS!F39/HistoricalFS!E39-1,0) -> 0.1588842 | G12: =IFERROR(HistoricalFS!G39/HistoricalFS!F39-1,0) -> 0.044219644 | H12: =IFERROR(HistoricalFS!H39/HistoricalFS!G39-1,0) -> 0.14382432 | J12: =AVERAGE(D12:H12) -> 0.10341395 | K12: =MEDIAN(D12:H12) -> 0.12983065
B13: Dividend Growth | D13: =IFERROR(HistoricalFS!D47/HistoricalFS!C47-1,0) -> 0.12624085 | E13: =IFERROR(HistoricalFS!E47/HistoricalFS!D47-1,0) -> -0.32840335 | F13: =IFERROR(HistoricalFS!F47/HistoricalFS!E47-1,0) -> 0.65930001 | G13: =IFERROR(HistoricalFS!G47/HistoricalFS!F47-1,0) -> 0.19407667 | H13: =IFERROR(HistoricalFS!H47/HistoricalFS!G47-1,0) -> 0.081301811 | J13: =AVERAGE(D13:H13) -> 0.1465032 | K13: =MEDIAN(D13:H13) -> 0.12624085
B15: Gross Margin | C15: =IFERROR(HistoricalFS!C16,0) -> 0.52476722 | D15: =IFERROR(HistoricalFS!D16,0) -> 0.48975258 | E15: =IFERROR(HistoricalFS!E16,0) -> 0.49154848 | F15: =IFERROR(HistoricalFS!F16,0) -> 0.51862945 | G15: =IFERROR(HistoricalFS!G16,0) -> 0.5189803 | H15: =IFERROR(HistoricalFS!H16,0) -> 0.50792037 | J15: =AVERAGE(C15:H15) -> 0.50859973 | K15: =MEDIAN(C15:H15) -> 0.51327491
B16: EBITDA Margin | C16: =IFERROR(HistoricalFS!C22,0) -> 0.14419656 | D16: =IFERROR(HistoricalFS!D22,0) -> 0.12500815 | E16: =IFERROR(HistoricalFS!E22,0) -> 0.13455396 | F16: =IFERROR(HistoricalFS!F22,0) -> 0.14665786 | G16: =IFERROR(HistoricalFS!G22,0) -> 0.1385061 | H16: =IFERROR(HistoricalFS!H22,0) -> 0.1442723 | J16: =AVERAGE(C16:H16) -> 0.13886582 | K16: =MEDIAN(C16:H16) -> 0.14135133
B17: EBIT Margin | C17: =IFERROR((HistoricalFS!C21-HistoricalFS!C27)/HistoricalFS!C9,0) -> 0.13725878 | D17: =IFERROR((HistoricalFS!D21-HistoricalFS!D27)/HistoricalFS!D9,0) -> 0.11805929 | E17: =IFERROR((HistoricalFS!E21-HistoricalFS!E27)/HistoricalFS!E9,0) -> 0.12687884 | F17: =IFERROR((HistoricalFS!F21-HistoricalFS!F27)/HistoricalFS!F9,0) -> 0.13817873 | G17: =IFERROR((HistoricalFS!G21-HistoricalFS!G27)/HistoricalFS!G9,0) -> 0.12928223 | H17: =IFERROR((HistoricalFS!H21-HistoricalFS!H27)/HistoricalFS!H9,0) -> 0.13342083 | J17: =AVERAGE(C17:H17) -> 0.13051311 | K17: =MEDIAN(C17:H17) -> 0.13135153
B18: EBT Margin | C18: =IFERROR(HistoricalFS!C34,0) -> 0.14062265 | D18: =IFERROR(HistoricalFS!D34,0) -> 0.1178548 | E18: =IFERROR(HistoricalFS!E34,0) -> 0.12617979 | F18: =IFERROR(HistoricalFS!F34,0) -> 0.14406986 | G18: =IFERROR(HistoricalFS!G34,0) -> 0.13880536 | H18: =IFERROR(HistoricalFS!H34,0) -> 0.14096333 | J18: =AVERAGE(C18:H18) -> 0.1347493 | K18: =MEDIAN(C18:H18) -> 0.13971401
B19: Net Profit Margin | C19: =IFERROR(HistoricalFS!C40,0) -> 0.10493163 | D19: =IFERROR(HistoricalFS!D40,0) -> 0.087562795 | E19: =IFERROR(HistoricalFS!E40,0) -> 0.094231131 | F19: =IFERROR(HistoricalFS!F40,0) -> 0.10724585 | G19: =IFERROR(HistoricalFS!G40,0) -> 0.10279366 | H19: =IFERROR(HistoricalFS!H40,0) -> 0.10470544 | J19: =AVERAGE(C19:H19) -> 0.10024508 | K19: =MEDIAN(C19:H19) -> 0.10374955
B21: Sales Expense % Revenue | C21: =IFERROR(HistoricalFS!C18/HistoricalFS!C9,0) -> 0.38057066 | D21: =IFERROR(HistoricalFS!D18/HistoricalFS!D9,0) -> 0.36474443 | E21: =IFERROR(HistoricalFS!E18/HistoricalFS!E9,0) -> 0.35699452 | F21: =IFERROR(HistoricalFS!F18/HistoricalFS!F9,0) -> 0.3719716 | G21: =IFERROR(HistoricalFS!G18/HistoricalFS!G9,0) -> 0.3804742 | H21: =IFERROR(HistoricalFS!H18/HistoricalFS!H9,0) -> 0.36364807 | J21: =AVERAGE(C21:H21) -> 0.36973391 | K21: =MEDIAN(C21:H21) -> 0.36835801
B22: Depreciation % Revenue | C22: =IFERROR(HistoricalFS!C27/HistoricalFS!C9,0) -> 0.0069377771 | D22: =IFERROR(HistoricalFS!D27/HistoricalFS!D9,0) -> 0.0069488698 | E22: =IFERROR(HistoricalFS!E27/HistoricalFS!E9,0) -> 0.0076751227 | F22: =IFERROR(HistoricalFS!F27/HistoricalFS!F9,0) -> 0.0084791315 | G22: =IFERROR(HistoricalFS!G27/HistoricalFS!G9,0) -> 0.0092238755 | H22: =IFERROR(HistoricalFS!H27/HistoricalFS!H9,0) -> 0.010851468 | J22: =AVERAGE(C22:H22) -> 0.0083527074 | K22: =MEDIAN(C22:H22) -> 0.0080771271
B23: Operating Income % Revenue | C23: =C17 -> 0.13725878 | D23: =D17 -> 0.11805929 | E23: =E17 -> 0.12687884 | F23: =F17 -> 0.13817873 | G23: =G17 -> 0.12928223 | H23: =H17 -> 0.13342083 | J23: =AVERAGE(C23:H23) -> 0.13051311 | K23: =MEDIAN(C23:H23) -> 0.13135153
B25: Return on Capital Employed (ROCE) | C25: =IFERROR(SUM(HistoricalFS!C33,HistoricalFS!C24)/SUM(HistoricalFS!C74:C75,HistoricalFS!C78),0) -> 0.56207134 | D25: =IFERROR(SUM(HistoricalFS!D33,HistoricalFS!D24)/SUM(HistoricalFS!D74:D75,HistoricalFS!D78),0) -> 0.48056118 | E25: =IFERROR(SUM(HistoricalFS!E33,HistoricalFS!E24)/SUM(HistoricalFS!E74:E75,HistoricalFS!E78),0) -> 0.44382341 | F25: =IFERROR(SUM(HistoricalFS!F33,HistoricalFS!F24)/SUM(HistoricalFS!F74:F75,HistoricalFS!F78),0) -> 0.43838235 | G25: =IFERROR(SUM(HistoricalFS!G33,HistoricalFS!G24)/SUM(HistoricalFS!G74:G75,HistoricalFS!G78),0) -> 0.39493441 | H25: =IFERROR(SUM(HistoricalFS!H33,HistoricalFS!H24)/SUM(HistoricalFS!H74:H75,HistoricalFS!H78),0) -> 0.38685906 | J25: =AVERAGE(C25:H25) -> 0.45110529 | K25: =MEDIAN(C25:H25) -> 0.44110288
B26: Retained Earnings % | C26: =IFERROR(HistoricalFS!C50,0) -> 0.47392408 | D26: =IFERROR(HistoricalFS!D50,0) -> 0.43047009 | E26: =IFERROR(HistoricalFS!E50,0) -> 0.66145866 | F26: =IFERROR(HistoricalFS!F50,0) -> 0.51527371 | G26: =IFERROR(HistoricalFS!G50,0) -> 0.44571015 | H26: =IFERROR(HistoricalFS!H50,0) -> 0.47600815 | J26: =AVERAGE(C26:H26) -> 0.50047414 | K26: =MEDIAN(C26:H26) -> 0.47496612
B27: Return on Equity (ROE) | C27: =IFERROR((HistoricalFS!C39/SUM(HistoricalFS!C74:C75)),0) -> 0.45396747 | D27: =IFERROR((HistoricalFS!D39/SUM(HistoricalFS!D74:D75)),0) -> 0.39349976 | E27: =IFERROR((HistoricalFS!E39/SUM(HistoricalFS!E74:E75)),0) -> 0.34323361 | F27: =IFERROR((HistoricalFS!F39/SUM(HistoricalFS!F74:F75)),0) -> 0.32936228 | G27: =IFERROR((HistoricalFS!G39/SUM(HistoricalFS!G74:G75)),0) -> 0.29926731 | H27: =IFERROR((HistoricalFS!H39/SUM(HistoricalFS!H74:H75)),0) -> 0.29464235 | J27: =AVERAGE(C27:H27) -> 0.3523288 | K27: =MEDIAN(C27:H27) -> 0.33629795
B28: Self Sustained Growth Rate | C28: =IFERROR(C27*C26,0) -> 0.21514612 | D28: =IFERROR(D27*D26,0) -> 0.16938988 | E28: =IFERROR(E27*E26,0) -> 0.22703485 | F28: =IFERROR(F27*F26,0) -> 0.16971173 | G28: =IFERROR(G27*G26,0) -> 0.13338648 | H28: =IFERROR(H27*H26,0) -> 0.14025216 | J28: =AVERAGE(C28:H28) -> 0.1758202 | K28: =MEDIAN(C28:H28) -> 0.1695508
B29: Interest Coverage Ratio | C29: =IFERROR((HistoricalFS!C33+HistoricalFS!C24)/HistoricalFS!C24,0) -> 23.823097 | D29: =IFERROR((HistoricalFS!D33+HistoricalFS!D24)/HistoricalFS!D24,0) -> 19.640323 | E29: =IFERROR((HistoricalFS!E33+HistoricalFS!E24)/HistoricalFS!E24,0) -> 27.096728 | F29: =IFERROR((HistoricalFS!F33+HistoricalFS!F24)/HistoricalFS!F24,0) -> 33.426948 | G29: =IFERROR((HistoricalFS!G33+HistoricalFS!G24)/HistoricalFS!G24,0) -> 54.347456 | H29: =IFERROR((HistoricalFS!H33+HistoricalFS!H24)/HistoricalFS!H24,0) -> 51.050102 | J29: =AVERAGE(C29:H29) -> 34.897442 | K29: =MEDIAN(C29:H29) -> 30.261838
B31: Debtor Turnover Ratio | C31: =IFERROR(HistoricalFS!C9/HistoricalFS!C65,0) -> 19.210092 | D31: =IFERROR(HistoricalFS!D9/HistoricalFS!D65,0) -> 18.134033 | E31: =IFERROR(HistoricalFS!E9/HistoricalFS!E65,0) -> 21.212323 | F31: =IFERROR(HistoricalFS!F9/HistoricalFS!F65,0) -> 21.466998 | G31: =IFERROR(HistoricalFS!G9/HistoricalFS!G65,0) -> 18.291452 | H31: =IFERROR(HistoricalFS!H9/HistoricalFS!H65,0) -> 21.748774 | J31: =AVERAGE(C31:H31) -> 20.010612 | K31: =MEDIAN(C31:H31) -> 20.211207
B32: Creditor Turnover Ratio | C32: =IFERROR(HistoricalFS!C9/SUM(HistoricalFS!C85:C86),0) -> 10.038148 | D32: =IFERROR(HistoricalFS!D9/SUM(HistoricalFS!D85:D86),0) -> 13.284263 | E32: =IFERROR(HistoricalFS!E9/SUM(HistoricalFS!E85:E86),0) -> 16.630456 | F32: =IFERROR(HistoricalFS!F9/SUM(HistoricalFS!F85:F86),0) -> 14.902294 | G32: =IFERROR(HistoricalFS!G9/SUM(HistoricalFS!G85:G86),0) -> 14.106235 | H32: =IFERROR(HistoricalFS!H9/SUM(HistoricalFS!H85:H86),0) -> 12.991228 | J32: =AVERAGE(C32:H32) -> 13.658771 | K32: =MEDIAN(C32:H32) -> 13.695249
B33: Inventory Turnover Ratio | C33: =IFERROR(HistoricalFS!C12/HistoricalFS!C64,0) -> 3.7581268 | D33: =IFERROR(HistoricalFS!D12/HistoricalFS!D64,0) -> 2.7446445 | E33: =IFERROR(HistoricalFS!E12/HistoricalFS!E64,0) -> 3.0159639 | F33: =IFERROR(HistoricalFS!F12/HistoricalFS!F64,0) -> 3.5099465 | G33: =IFERROR(HistoricalFS!G12/HistoricalFS!G64,0) -> 3.5740436 | H33: =IFERROR(HistoricalFS!H12/HistoricalFS!H64,0) -> 3.1950756 | J33: =AVERAGE(C33:H33) -> 3.2996335 | K33: =MEDIAN(C33:H33) -> 3.352511
B34: Fixed Asset Turnover Ratio | C34: =IFERROR(HistoricalFS!C9/HistoricalFS!C54,0) -> 19.74535 | D34: =IFERROR(HistoricalFS!D9/HistoricalFS!D54,0) -> 18.558713 | E34: =IFERROR(HistoricalFS!E9/HistoricalFS!E54,0) -> 15.234725 | F34: =IFERROR(HistoricalFS!F9/HistoricalFS!F54,0) -> 14.233276 | G34: =IFERROR(HistoricalFS!G9/HistoricalFS!G54,0) -> 13.232345 | H34: =IFERROR(HistoricalFS!H9/HistoricalFS!H54,0) -> 10.443193 | J34: =AVERAGE(C34:H34) -> 15.241267 | K34: =MEDIAN(C34:H34) -> 14.734
B35: Capital Turnover Ratio | C35: =IFERROR(HistoricalFS!C9/SUM(HistoricalFS!C74:C75,HistoricalFS!C78),0) -> 3.8292393 | D35: =IFERROR(HistoricalFS!D9/SUM(HistoricalFS!D74:D75,HistoricalFS!D78),0) -> 3.8699577 | E35: =IFERROR(HistoricalFS!E9/SUM(HistoricalFS!E74:E75,HistoricalFS!E78),0) -> 3.3875805 | F35: =IFERROR(HistoricalFS!F9/SUM(HistoricalFS!F74:F75,HistoricalFS!F78),0) -> 2.9518161 | G35: =IFERROR(HistoricalFS!G9/SUM(HistoricalFS!G74:G75,HistoricalFS!G78),0) -> 2.7928861 | H35: =IFERROR(HistoricalFS!H9/SUM(HistoricalFS!H74:H75,HistoricalFS!H78),0) -> 2.6906362 | J35: =AVERAGE(C35:H35) -> 3.253686 | K35: =MEDIAN(C35:H35) -> 3.1696983
B37: Debtor Days | C37: =IFERROR(365/C31,0) -> 19.000429 | D37: =IFERROR(365/D31,0) -> 20.1279 | E37: =IFERROR(365/E31,0) -> 17.20698 | F37: =IFERROR(365/F31,0) -> 17.002843 | G37: =IFERROR(365/G31,0) -> 19.954676 | H37: =IFERROR(365/H31,0) -> 16.782555 | J37: =AVERAGE(C37:H37) -> 18.345897 | K37: =MEDIAN(C37:H37) -> 18.103704
B38: Payable Days | C38: =IFERROR(365/C32,0) -> 36.361288 | D38: =IFERROR(365/D32,0) -> 27.47612 | E38: =IFERROR(365/E32,0) -> 21.947685 | F38: =IFERROR(365/F32,0) -> 24.492874 | G38: =IFERROR(365/G32,0) -> 25.875084 | H38: =IFERROR(365/H32,0) -> 28.095881 | J38: =AVERAGE(C38:H38) -> 27.374822 | K38: =MEDIAN(C38:H38) -> 26.675602
B39: Inventory Days | C39: =IFERROR(365/C33,0) -> 97.122854 | D39: =IFERROR(365/D33,0) -> 132.98626 | E39: =IFERROR(365/E33,0) -> 121.02267 | F39: =IFERROR(365/F33,0) -> 103.99019 | G39: =IFERROR(365/G33,0) -> 102.12522 | H39: =IFERROR(365/H33,0) -> 114.2383 | J39: =AVERAGE(C39:H39) -> 111.91425 | K39: =MEDIAN(C39:H39) -> 109.11424
B40: Cash Conversion Cycle (days) | C40: =IFERROR(C37+C39-C38,0) -> 79.761995 | D40: =IFERROR(D37+D39-D38,0) -> 125.63804 | E40: =IFERROR(E37+E39-E38,0) -> 116.28196 | F40: =IFERROR(F37+F39-F38,0) -> 96.500159 | G40: =IFERROR(G37+G39-G38,0) -> 96.204816 | H40: =IFERROR(H37+H39-H38,0) -> 102.92497 | J40: =AVERAGE(C40:H40) -> 102.88532 | K40: =MEDIAN(C40:H40) -> 99.712565
B42: CFO/Sales | C42: =IFERROR(HistoricalFS!C98/HistoricalFS!C9,0) -> 0.24586738 | D42: =IFERROR(HistoricalFS!D98/HistoricalFS!D9,0) -> -0.054437215 | E42: =IFERROR(HistoricalFS!E98/HistoricalFS!E9,0) -> 0.091733504 | F42: =IFERROR(HistoricalFS!F98/HistoricalFS!F9,0) -> 0.17015081 | G42: =IFERROR(HistoricalFS!G98/HistoricalFS!G9,0) -> 0.091339366 | H42: =IFERROR(HistoricalFS!H98/HistoricalFS!H9,0) -> 0.069911 | J42: =AVERAGE(C42:H42) -> 0.10242747 | K42: =MEDIAN(C42:H42) -> 0.091536435
B43: CFO/Total Assets | C43: =IFERROR(HistoricalFS!C98/HistoricalFS!C71,0) -> 0.48193291 | D43: =IFERROR(HistoricalFS!D98/HistoricalFS!D71,0) -> -0.12727552 | E43: =IFERROR(HistoricalFS!E98/HistoricalFS!E71,0) -> 0.20040975 | F43: =IFERROR(HistoricalFS!F98/HistoricalFS!F71,0) -> 0.33116616 | G43: =IFERROR(HistoricalFS!G98/HistoricalFS!G71,0) -> 0.17453538 | H43: =IFERROR(HistoricalFS!H98/HistoricalFS!H71,0) -> 0.12727542 | J43: =AVERAGE(C43:H43) -> 0.19800735 | K43: =MEDIAN(C43:H43) -> 0.18747256
B44: CFO/Total Debt | C44: =IFERROR(HistoricalFS!C98/SUM(HistoricalFS!C78,HistoricalFS!C84),0) -> 5.0346571 | D44: =IFERROR(HistoricalFS!D98/SUM(HistoricalFS!D78,HistoricalFS!D84),0) -> -1.2016945 | E44: =IFERROR(HistoricalFS!E98/SUM(HistoricalFS!E78,HistoricalFS!E84),0) -> 2.1806152 | F44: =IFERROR(HistoricalFS!F98/SUM(HistoricalFS!F78,HistoricalFS!F84),0) -> 5.5569519 | G44: =IFERROR(HistoricalFS!G98/SUM(HistoricalFS!G78,HistoricalFS!G84),0) -> 4.4067793 | H44: =IFERROR(HistoricalFS!H98/SUM(HistoricalFS!H78,HistoricalFS!H84),0) -> 2.9805738 | J44: =AVERAGE(C44:H44) -> 3.1596471 | K44: =MEDIAN(C44:H44) -> 3.6936765

Sheet Forecasting
B2: Hawkins Cookers Limited
O4: (Values in Rs. Lakhs)
B7: Hawkins Cookers Limited - Revenue Forecasting | G7: Hawkins Cookers Limited - EBITDA Forecasting | L7: Hawkins Cookers Limited - Net Profit Forecasting
B8: Year Weight | C8: Year | D8: Revenue | E8: Growth | G8: Year Weight | H8: Year | I8: EBITDA | J8: Growth | L8: Year Weight | M8: Year | N8: Net Profit | O8: Growth
B9: 1 | C9: 2021 | D9: {=TRANSPOSE(HistoricalFS!C9:H9)} -> 76845.94 | G9: 1 | H9: 2021 | I9: {=TRANSPOSE(HistoricalFS!C21:H21)} -> 11080.92 | L9: 1 | M9: 2021 | N9: {=TRANSPOSE(HistoricalFS!C39:H39)} -> 8063.57
B10: =B9+1 -> 2 | C10: =C9+1 -> 2022 | D10: 95801.19 | E10: =D10/D9-1 -> 0.2466656 | G10: =G9+1 -> 2 | H10: =H9+1 -> 2022 | I10: 11975.93 | J10: =I10/I9-1 -> 0.080770369 | L10: =L9+1 -> 2 | M10: =M9+1 -> 2022 | N10: 8388.62 | O10: =N10/N9-1 -> 0.040310929
B11: =B10+1 -> 3 | C11: =C10+1 -> 2023 | D11: 100579.5 | E11: =D11/D10-1 -> 0.049877355 | G11: =G10+1 -> 3 | H11: =H10+1 -> 2023 | I11: 13533.37 | J11: =I11/I10-1 -> 0.13004752 | L11: =L10+1 -> 3 | M11: =M10+1 -> 2023 | N11: 9477.72 | O11: =N11/N10-1 -> 0.12983065
B12: =B11+1 -> 4 | C12: =C11+1 -> 2024 | D12: 102414.97 | E12: =D12/D11-1 -> 0.018248947 | G12: =G11+1 -> 4 | H12: =H11+1 -> 2024 | I12: 15019.96 | J12: =I12/I11-1 -> 0.10984625 | L12: =L11+1 -> 4 | M12: =M11+1 -> 2024 | N12: 10983.58 | O12: =N12/N11-1 -> 0.1588842
B13: =B12+1 -> 5 | C13: =C12+1 -> 2025 | D13: 111575.66 | E13: =D13/D12-1 -> 0.089446787 | G13: =G12+1 -> 5 | H13: =H12+1 -> 2025 | I13: 15453.91 | J13: =I13/I12-1 -> 0.028891555 | L13: =L12+1 -> 5 | M13: =M12+1 -> 2025 | N13: 11469.27 | O13: =N13/N12-1 -> 0.044219644
B14: =B13+1 -> 6 | C14: =C13+1 -> 2026 | D14: 125292.73 | E14: =D14/D13-1 -> 0.12293963 | G14: =G13+1 -> 6 | H14: =H13+1 -> 2026 | I14: 18076.27 | J14: =I14/I13-1 -> 0.16968909 | L14: =L13+1 -> 6 | M14: =M13+1 -> 2026 | N14: 13118.83 | O14: =N14/N13-1 -> 0.14382432
B15: =B14+1 -> 7 | C15: =C14+1 -> 2027 | D15: =FORECAST(B15,$D$9:$D$14,$B$9:$B$14) -> 131224.28 | E15: =D15/D14-1 -> 0.047341544 | G15: =G14+1 -> 7 | H15: =H14+1 -> 2027 | I15: =FORECAST(G15,$I$9:$I$14,$G$9:$G$14) -> 18879.788 | J15: =I15/I14-1 -> 0.044451538 | L15: =L14+1 -> 7 | M15: =M14+1 -> 2027 | N15: =FORECAST(L15,$N$9:$N$14,$L$9:$L$14) -> 13852.676 | O15: =N15/N14-1 -> 0.055938373
B16: =B15+1 -> 8 | C16: =C15+1 -> 2028 | D16: =FORECAST(B16,$D$9:$D$14,$B$9:$B$14) -> 139549.79 | E16: =D16/D15-1 -> 0.063444885 | G16: =G15+1 -> 8 | H16: =H15+1 -> 2028 | I16: =FORECAST(G16,$I$9:$I$14,$G$9:$G$14) -> 20219.71 | J16: =I16/I15-1 -> 0.070971257 | L16: =L15+1 -> 8 | M16: =M15+1 -> 2028 | N16: =FORECAST(L16,$N$9:$N$14,$L$9:$L$14) -> 14881.936 | O16: =N16/N15-1 -> 0.074300466
B17: =B16+1 -> 9 | C17: =C16+1 -> 2029 | D17: =FORECAST(B17,$D$9:$D$14,$B$9:$B$14) -> 147875.3 | E17: =D17/D16-1 -> 0.059659777 | G17: =G16+1 -> 9 | H17: =H16+1 -> 2029 | I17: =FORECAST(G17,$I$9:$I$14,$G$9:$G$14) -> 21559.633 | J17: =I17/I16-1 -> 0.066268125 | L17: =L16+1 -> 9 | M17: =M16+1 -> 2029 | N17: =FORECAST(L17,$N$9:$N$14,$L$9:$L$14) -> 15911.197 | O17: =N17/N16-1 -> 0.069161718
B18: =B17+1 -> 10 | C18: =C17+1 -> 2030 | D18: =FORECAST(B18,$D$9:$D$14,$B$9:$B$14) -> 156200.81 | E18: =D18/D17-1 -> 0.056300879 | G18: =G17+1 -> 10 | H18: =H17+1 -> 2030 | I18: =FORECAST(G18,$I$9:$I$14,$G$9:$G$14) -> 22899.555 | J18: =I18/I17-1 -> 0.062149588 | L18: =L17+1 -> 10 | M18: =M17+1 -> 2030 | N18: =FORECAST(L18,$N$9:$N$14,$L$9:$L$14) -> 16940.457 | O18: =N18/N17-1 -> 0.064687799
B19: =B18+1 -> 11 | C19: =C18+1 -> 2031 | D19: =FORECAST(B19,$D$9:$D$14,$B$9:$B$14) -> 164526.32 | E19: =D19/D18-1 -> 0.05330004 | G19: =G18+1 -> 11 | H19: =H18+1 -> 2031 | I19: =FORECAST(G19,$I$9:$I$14,$G$9:$G$14) -> 24239.477 | J19: =I19/I18-1 -> 0.058513028 | L19: =L18+1 -> 11 | M19: =M18+1 -> 2031 | N19: =FORECAST(L19,$N$9:$N$14,$L$9:$L$14) -> 17969.717 | O19: =N19/N18-1 -> 0.060757528
C22: Revenue | H22: EBITDA | M22: Net Profit

Sheet WACC
B2: Hawkins Cookers Limited
B7: Weighted Average Cost of Capital
B9: All figures are in INR unless stated otherwise.
B11: Peer Companies | I11: (Values in Rs. Crore)
G12: Debt / | H12: Debt / | I12: Levered | J12: Unlevered
B13: Name | C13: Country | D13: Total Debt | E13: Total Equity | F13: Tax Rate 1 | G13: Equity | H13: Capital | I13: Beta 2 | J13: Beta 3
B15: Cello World | C15: India | D15: ='Beta - Comps'!F7 -> 38.11 | E15: ='Beta - Comps'!E7 -> 8340.62 | F15: 0.3 | G15: =D15/E15 -> 0.0045692047 | H15: =D15/(E15+D15) -> 0.004548422 | I15: 1.18 | J15: =I15/1+(1-F15)*G15 -> 1.1831984
B16: Borosil | C16: India | D16: ='Beta - Comps'!F9 -> 148.08 | E16: ='Beta - Comps'!E9 -> 2852.76 | F16: 0.3 | G16: =D16/E16 -> 0.051907626 | H16: =D16/(E16+D16) -> 0.049346183 | I16: 1.29 | J16: =I16/1+(1-F16)*G16 -> 1.3263353
B17: All Time Plastic | C17: India | D17: ='Beta - Comps'!F10 -> 86.4 | E17: ='Beta - Comps'!E10 -> 1411.95 | F17: 0.3 | G17: =D17/E17 -> 0.061191969 | H17: =D17/(E17+D17) -> 0.05766343 | I17: 0.52 | J17: =I17/1+(1-F17)*G17 -> 0.56283438
B18: Clay Craft India | C18: India | D18: 49.98 | E18: 332.42 | F18: 0.3 | G18: =D18/E18 -> 0.15035196 | H18: =D18/(E18+D18) -> 0.13070084 | I18: 0.82 | J18: =I18/1+(1-F18)*G18 -> 0.92524638
B19: Hawkins Cookers | C19: India | D19: ='Beta - Comps'!F8 -> 29.39 | E19: ='Beta - Comps'!E8 -> 4417.68 | F19: 0.3 | G19: =D19/E19 -> 0.0066528132 | H19: =D19/(E19+D19) -> 0.0066088458 | I19: ='Beta - Regression'!M13 -> 0.18276103 | J19: =I19/1+(1-F19)*G19 -> 0.18741799
E21: Average | F21: =AVERAGE(F15:F19) -> 0.3 | G21: =AVERAGE(G15:G19) -> 0.054934715 | H21: =AVERAGE(H15:H19) -> 0.049773544 | I21: =AVERAGE(I15:I19) -> 0.79855221 | J21: =AVERAGE(J15:J19) -> 0.83700651
E22: Median | F22: =MEDIAN(F15:F19) -> 0.3 | G22: =MEDIAN(G15:G19) -> 0.051907626 | H22: =MEDIAN(H15:H19) -> 0.049346183 | I22: =MEDIAN(I15:I19) -> 0.82 | J22: =MEDIAN(J15:J19) -> 0.92524638
B25: Cost of Debt | G25: Cost of Equity
B27: Pre-tax Cost of Debt | E27: =HistoricalFS!H24/(SUM(HistoricalFS!H78,HistoricalFS!H84)) -> 0.12007581 | G27: Risk Free Rate | J27: 0.0676
B28: Tax Rate | E28: =F22 -> 0.3 | G28: Equity Risk Premium | J28: =Rm!F13-J27 -> 0.096892308
B29: After Tax Cost of Debt | E29: =E27*(1-E28) -> 0.084053069 | G29: Levered Beta 4 | J29: =J38 -> 1.1884121
G30: Cost of Equity | J30: =J27+(J28)*J29 -> 0.18274799
B33: Capital Structure | G33: Levered Beta
D35: Current | E35: Target | G35: Comps Median Unlevered Beta | J35: =J22 -> 0.92524638
B36: Total Debt | C36: =D19 -> 29.39 | D36: =C36/$C$38 -> 0.0066088458 | E36: =H22 -> 0.049346183 | G36: Target Debt/Equity | J36: =E40 -> 0.051907626
B37: Market Capitalization | C37: =E19 -> 4417.68 | D37: =100%-D36 -> 0.99339115 | E37: =E38-E36 -> 0.95065382 | G37: Tax Rate | J37: =F22 -> 0.3
B38: Total Capitalization | C38: =C36+C37 -> 4447.07 | D38: =D37+D36 -> 1 | E38: =D38 -> 1 | G38: Levered Beta | J38: =J35*(1+(1-J36)*J37) -> 1.1884121
B40: Debt / Equity | D40: =D36/D37 -> 0.0066528132 | E40: =E36/E37 -> 0.051907626 | G40: Weighted Average Cost of Capital
G42: Cost of Equity | J42: =J30 -> 0.18274799
G43: Equity Weight | J43: =E37 -> 0.95065382
B45: 1. Tax Rate considered as Marginal Tax Rate for the Country | G45: Cost of Debt | J45: =E29 -> 0.084053069
B46: 2. Levered Beta is based on 2 year daily data | G46: Debt Weight | J46: =E36 -> 0.049346183
B47: 3. Unlevered Beta = Levered Beta/(1+(1-Tax Rate) x Debt/Equity)
B48: 4. Levered Beta = Unlevered Beta*(1+(1-Tax Rate) x Debt/Equity | G48: WACC | J48: =(J42*J43)+(J45*J46) -> 0.17787777

Sheet Common Size Statement
B2: Hawkins Cookers Limited
B6: Common Size Income Statement - Hawkins Cookers Limited
B8: Particulars | C8: =HistoricalFS!C7 -> 2021 | D8: =HistoricalFS!D7 -> 2022 | E8: =HistoricalFS!E7 -> 2023 | F8: =HistoricalFS!F7 -> 2024 | G8: =HistoricalFS!G7 -> 2025 | H8: =HistoricalFS!H7 -> 2026
B10: ='Income Statement'!A5 -> Revenue from operations (net) | C10: ='Income Statement'!B5/'Income Statement'!B$5 -> 1 | D10: ='Income Statement'!C5/'Income Statement'!C$5 -> 1 | E10: ='Income Statement'!D5/'Income Statement'!D$5 -> 1 | F10: ='Income Statement'!E5/'Income Statement'!E$5 -> 1 | G10: ='Income Statement'!F5/'Income Statement'!F$5 -> 1 | H10: ='Income Statement'!G5/'Income Statement'!G$5 -> 1
B11: ='Income Statement'!A6 -> Other Income | C11: ='Income Statement'!B6/'Income Statement'!B$5 -> 0.0095252918 | D11: ='Income Statement'!C6/'Income Statement'!C$5 -> 0.0061180868 | E11: ='Income Statement'!D6/'Income Statement'!D$5 -> 0.0041360317 | F11: ='Income Statement'!E6/'Income Statement'!E$5 -> 0.010334036 | G11: ='Income Statement'!F6/'Income Statement'!F$5 -> 0.012125046 | H11: ='Income Statement'!G6/'Income Statement'!G$5 -> 0.010358941
B12: ='Income Statement'!A9 -> Cost of materials consumed | C12: ='Income Statement'!B9/'Income Statement'!B5 -> 0.3202652 | D12: ='Income Statement'!C9/'Income Statement'!C5 -> 0.41041192 | E12: ='Income Statement'!D9/'Income Statement'!D5 -> 0.40231339 | F12: ='Income Statement'!E9/'Income Statement'!E5 -> 0.34528692 | G12: ='Income Statement'!F9/'Income Statement'!F5 -> 0.37990275 | H12: ='Income Statement'!G9/'Income Statement'!G5 -> 0.38830298
B13: ='Income Statement'!A10 -> Purchases of Stock-in-Trade | C13: ='Income Statement'!B10/'Income Statement'!B5 -> 0.10911702 | D13: ='Income Statement'!C10/'Income Statement'!C5 -> 0.15660933 | E13: ='Income Statement'!D10/'Income Statement'!D5 -> 0.10460859 | F13: ='Income Statement'!E10/'Income Statement'!E5 -> 0.11832548 | G13: ='Income Statement'!F10/'Income Statement'!F5 -> 0.10588465 | H13: ='Income Statement'!G10/'Income Statement'!G5 -> 0.11482095
B14: Changes in inventories of Finished Goods, Work-in-Progress and Stock-in-Trade | C14: ='Income Statement'!B11/'Income Statement'!B5 -> 0.045850568 | D14: ='Income Statement'!C11/'Income Statement'!C5 -> -0.056773825 | E14: ='Income Statement'!D11/'Income Statement'!D5 -> 0.0015295363 | F14: ='Income Statement'!E11/'Income Statement'!E5 -> 0.017758146 | G14: ='Income Statement'!F11/'Income Statement'!F5 -> -0.0047677065 | H14: ='Income Statement'!G11/'Income Statement'!G5 -> -0.011044296
B15: ='Income Statement'!A12 -> Employee benefits expense | C15: ='Income Statement'!B12/'Income Statement'!B5 -> 0.13136478 | D15: ='Income Statement'!C12/'Income Statement'!C5 -> 0.11083965 | E15: ='Income Statement'!D12/'Income Statement'!D5 -> 0.11208576 | F15: ='Income Statement'!E12/'Income Statement'!E5 -> 0.11296503 | G15: ='Income Statement'!F12/'Income Statement'!F5 -> 0.10978918 | H15: ='Income Statement'!G12/'Income Statement'!G5 -> 0.10266134
B16: ='Income Statement'!A13 -> Finance costs | C16: ='Income Statement'!B13/'Income Statement'!B5 -> 0.0061614185 | D16: ='Income Statement'!C13/'Income Statement'!C5 -> 0.0063225728 | E16: ='Income Statement'!D13/'Income Statement'!D5 -> 0.0048350807 | F16: ='Income Statement'!E13/'Income Statement'!E5 -> 0.0044429052 | G16: ='Income Statement'!F13/'Income Statement'!F5 -> 0.0026019116 | H16: ='Income Statement'!G13/'Income Statement'!G5 -> 0.0028164443
B17: ='Income Statement'!A14 -> Depreciation and amortization expense | C17: ='Income Statement'!B14/'Income Statement'!B5 -> 0.0069377771 | D17: ='Income Statement'!C14/'Income Statement'!C5 -> 0.0069488698 | E17: ='Income Statement'!D14/'Income Statement'!D5 -> 0.0076751227 | F17: ='Income Statement'!E14/'Income Statement'!E5 -> 0.0084791315 | G17: ='Income Statement'!F14/'Income Statement'!F5 -> 0.0092238755 | H17: ='Income Statement'!G14/'Income Statement'!G5 -> 0.010851468
B18: ='Income Statement'!A15 -> Other expenses | C18: ='Income Statement'!B15/'Income Statement'!B5 -> 0.24920588 | D18: ='Income Statement'!C15/'Income Statement'!C5 -> 0.25390478 | E18: ='Income Statement'!D15/'Income Statement'!D5 -> 0.24490875 | F18: ='Income Statement'!E15/'Income Statement'!E5 -> 0.25900657 | G18: ='Income Statement'!F15/'Income Statement'!F5 -> 0.27068502 | H18: ='Income Statement'!G15/'Income Statement'!G5 -> 0.26098673
B19: ='Income Statement'!A17 -> Profit before tax | C19: ='Income Statement'!B17/'Income Statement'!B5 -> 0.14062239 | D19: ='Income Statement'!C17/'Income Statement'!C5 -> 0.1178549 | E19: ='Income Statement'!D17/'Income Statement'!D5 -> 0.12617969 | F19: ='Income Statement'!E17/'Income Statement'!E5 -> 0.14406995 | G19: ='Income Statement'!F17/'Income Statement'!F5 -> 0.13880536 | H19: ='Income Statement'!G17/'Income Statement'!G5 -> 0.14096333
B20: ='Income Statement'!A19 -> Current tax | C20: ='Income Statement'!B19/'Income Statement'!B5 -> 0.034940037 | D20: ='Income Statement'!C19/'Income Statement'!C5 -> 0.029509028 | E20: ='Income Statement'!D19/'Income Statement'!D5 -> 0.032685885 | F20: ='Income Statement'!E19/'Income Statement'!E5 -> 0.036703619 | G20: ='Income Statement'!F19/'Income Statement'!F5 -> 0.034946063 | H20: ='Income Statement'!G19/'Income Statement'!G5 -> 0.035620582
B21: ='Income Statement'!A20 -> Deferred tax | C21: ='Income Statement'!B20/'Income Statement'!B5 -> 0.00075098307 | D21: ='Income Statement'!C20/'Income Statement'!C5 -> 0.00078297566 | E21: ='Income Statement'!D20/'Income Statement'!D5 -> -0.00073722777 | F21: ='Income Statement'!E20/'Income Statement'!E5 -> 0.00012039256 | G21: ='Income Statement'!F20/'Income Statement'!F5 -> 0.0010656446 | H21: ='Income Statement'!G20/'Income Statement'!G5 -> 0.00063730753
B22: ='Income Statement'!A21 -> Profit for the year (A) | C22: ='Income Statement'!B21/'Income Statement'!B5 -> 0.10493137 | D22: ='Income Statement'!C21/'Income Statement'!C5 -> 0.0875629 | E22: ='Income Statement'!D21/'Income Statement'!D5 -> 0.094231031 | F22: ='Income Statement'!E21/'Income Statement'!E5 -> 0.10724604 | G22: ='Income Statement'!F21/'Income Statement'!F5 -> 0.10279366 | H22: ='Income Statement'!G21/'Income Statement'!G5 -> 0.10470544
B23: EBITDA | C23: =HistoricalFS!C21/HistoricalFS!C9 -> 0.14419656 | D23: =HistoricalFS!D21/HistoricalFS!D9 -> 0.12500815 | E23: =HistoricalFS!E21/HistoricalFS!E9 -> 0.13455396 | F23: =HistoricalFS!F21/HistoricalFS!F9 -> 0.14665786 | G23: =HistoricalFS!G21/HistoricalFS!G9 -> 0.1385061 | H23: =HistoricalFS!H21/HistoricalFS!H9 -> 0.1442723
B25: Common Size Balance Sheet - Hawkins Cookers Limited
B27: Particulars | C27: 2021 | D27: 2022 | E27: 2023 | F27: 2024 | G27: 2025 | H27: 2026
B29: =HistoricalFS!B53 -> NON-CURRENT ASSETS
B30: =HistoricalFS!B54 -> Property, Plant and Equipment | C30: =HistoricalFS!C54/HistoricalFS!C$71 -> 0.099270644 | D30: =HistoricalFS!D54/HistoricalFS!D$71 -> 0.12597986 | E30: =HistoricalFS!E54/HistoricalFS!E$71 -> 0.14340234 | F30: =HistoricalFS!F54/HistoricalFS!F$71 -> 0.13674362 | G30: =HistoricalFS!G54/HistoricalFS!G$71 -> 0.14440714 | H30: =HistoricalFS!H54/HistoricalFS!H$71 -> 0.17432743
B31: =HistoricalFS!B55 -> Capital Work-in-Progress | C31: =HistoricalFS!C55/HistoricalFS!C$71 -> 0.0070905234 | D31: =HistoricalFS!D55/HistoricalFS!D$71 -> 0.0078854861 | E31: =HistoricalFS!E55/HistoricalFS!E$71 -> 0.0046906669 | F31: =HistoricalFS!F55/HistoricalFS!F$71 -> 0.022581114 | G31: =HistoricalFS!G55/HistoricalFS!G$71 -> 0.038450104 | H31: =HistoricalFS!H55/HistoricalFS!H$71 -> 0.017363361
B32: =HistoricalFS!B56 -> Intangible assets | C32: =HistoricalFS!C56/HistoricalFS!C$71 -> 0.00024206442 | D32: =HistoricalFS!D56/HistoricalFS!D$71 -> 0.00041952123 | E32: =HistoricalFS!E56/HistoricalFS!E$71 -> 0.00033189808 | F32: =HistoricalFS!F56/HistoricalFS!F$71 -> 0.00022557928 | G32: =HistoricalFS!G56/HistoricalFS!G$71 -> 0.00078745363 | H32: =HistoricalFS!H56/HistoricalFS!H$71 -> 0.0010017156
B33: =HistoricalFS!B57 -> Investments | C33: =HistoricalFS!C57/HistoricalFS!C$71 -> 6.3768287e-06 | D33: =HistoricalFS!D57/HistoricalFS!D$71 -> 6.1012396e-06 | E33: =HistoricalFS!E57/HistoricalFS!E$71 -> 5.4302696e-06 | F33: =HistoricalFS!F57/HistoricalFS!F$71 -> 4.751038e-06 | G33: =HistoricalFS!G57/HistoricalFS!G$71 -> 4.2815008e-06 | H33: =HistoricalFS!H57/HistoricalFS!H$71 -> 3.6325631e-06
B34: =HistoricalFS!B58 -> Other non-current financial assets | C34: =HistoricalFS!C58/HistoricalFS!C$71 -> 0.028303427 | D34: =HistoricalFS!D58/HistoricalFS!D$71 -> 0.0031841149 | E34: =HistoricalFS!E58/HistoricalFS!E$71 -> 0.016928105 | F34: =HistoricalFS!F58/HistoricalFS!F$71 -> 0.0084728111 | G34: =HistoricalFS!G58/HistoricalFS!G$71 -> 0.016030624 | H34: =HistoricalFS!H58/HistoricalFS!H$71 -> 0.0078919612
B35: =HistoricalFS!B59 -> Non-current tax assets (net) | C35: =HistoricalFS!C59/HistoricalFS!C$71 -> 0.0053213361 | D35: =HistoricalFS!D59/HistoricalFS!D$71 -> 0.0077292943 | E35: =HistoricalFS!E59/HistoricalFS!E$71 -> 0.0064311769 | F35: =HistoricalFS!F59/HistoricalFS!F$71 -> 0.0059895386 | G35: =HistoricalFS!G59/HistoricalFS!G$71 -> 0.0075911009 | H35: =HistoricalFS!H59/HistoricalFS!H$71 -> 0.0061279886
B36: =HistoricalFS!B60 -> Deferred tax assets (net) | C36: =HistoricalFS!C60/HistoricalFS!C$71 -> 0.0021882726 | D36: =HistoricalFS!D60/HistoricalFS!D$71 -> 0.00088589999 | E36: =HistoricalFS!E60/HistoricalFS!E$71 -> 0.0024718587 | F36: =HistoricalFS!F60/HistoricalFS!F$71 -> 0.0016778766 | G36: =HistoricalFS!G60/HistoricalFS!G$71 -> 0.00032488028 | H36: =HistoricalFS!H60/HistoricalFS!H$71 -> 0
B37: =HistoricalFS!B61 -> Other non-current assets | C37: =HistoricalFS!C61/HistoricalFS!C$71 -> 0.0093094048 | D37: =HistoricalFS!D61/HistoricalFS!D$71 -> 0.012722793 | E37: =HistoricalFS!E61/HistoricalFS!E$71 -> 0.012078657 | F37: =HistoricalFS!F61/HistoricalFS!F$71 -> 0.013001691 | G37: =HistoricalFS!G61/HistoricalFS!G$71 -> 0.010719679 | H37: =HistoricalFS!H61/HistoricalFS!H$71 -> 0.0097191404
B38: =HistoricalFS!B63 -> CURRENT ASSETS
B39: =HistoricalFS!B64 -> Inventories | C39: =HistoricalFS!C64/HistoricalFS!C$71 -> 0.2478681 | D39: =HistoricalFS!D64/HistoricalFS!D$71 -> 0.43465402 | E39: =HistoricalFS!E64/HistoricalFS!E$71 -> 0.36831064 | F39: =HistoricalFS!F64/HistoricalFS!F$71 -> 0.26692605 | G39: =HistoricalFS!G64/HistoricalFS!G$71 -> 0.25717485 | H39: =HistoricalFS!H64/HistoricalFS!H$71 -> 0.28038403
B40: =HistoricalFS!B65 -> Trade receivables | C40: =HistoricalFS!C65/HistoricalFS!C$71 -> 0.10203666 | D40: =HistoricalFS!D65/HistoricalFS!D$71 -> 0.12893017 | E40: =HistoricalFS!E65/HistoricalFS!E$71 -> 0.1029918 | F40: =HistoricalFS!F65/HistoricalFS!F$71 -> 0.090665199 | G40: =HistoricalFS!G65/HistoricalFS!G$71 -> 0.10446656 | H40: =HistoricalFS!H65/HistoricalFS!H$71 -> 0.083707475
B41: =HistoricalFS!B66 -> Cash and cash equivalents | C41: =HistoricalFS!C66/HistoricalFS!C$71 -> 0.054421642 | D41: =HistoricalFS!D66/HistoricalFS!D$71 -> 0.0076978119 | E41: =HistoricalFS!E66/HistoricalFS!E$71 -> 0.024855647 | F41: =HistoricalFS!F66/HistoricalFS!F$71 -> 0.022922998 | G41: =HistoricalFS!G66/HistoricalFS!G$71 -> 0.01839778 | H41: =HistoricalFS!H66/HistoricalFS!H$71 -> 0.022804504
B42: =HistoricalFS!B67 -> Bank balances other than above | C42: =HistoricalFS!C67/HistoricalFS!C$71 -> 0.37176095 | D42: =HistoricalFS!D67/HistoricalFS!D$71 -> 0.1512734 | E42: =HistoricalFS!E67/HistoricalFS!E$71 -> 0.18919798 | F42: =HistoricalFS!F67/HistoricalFS!F$71 -> 0.33502173 | G42: =HistoricalFS!G67/HistoricalFS!G$71 -> 0.30655648 | H42: =HistoricalFS!H67/HistoricalFS!H$71 -> 0.25460867
B43: =HistoricalFS!B68 -> Other current financial assets | C43: =HistoricalFS!C68/HistoricalFS!C$71 -> 0.013352314 | D43: =HistoricalFS!D68/HistoricalFS!D$71 -> 0.0059077083 | E43: =HistoricalFS!E68/HistoricalFS!E$71 -> 0.005149416 | F43: =HistoricalFS!F68/HistoricalFS!F$71 -> 0.0093297084 | G43: =HistoricalFS!G68/HistoricalFS!G$71 -> 0.010150753 | H43: =HistoricalFS!H68/HistoricalFS!H$71 -> 0.0066024013
B44: =HistoricalFS!B69 -> Other current assets | C44: =HistoricalFS!C69/HistoricalFS!C$71 -> 0.058828286 | D44: =HistoricalFS!D69/HistoricalFS!D$71 -> 0.11272382 | E44: =HistoricalFS!E69/HistoricalFS!E$71 -> 0.12315439 | F44: =HistoricalFS!F69/HistoricalFS!F$71 -> 0.086437345 | G44: =HistoricalFS!G69/HistoricalFS!G$71 -> 0.084938297 | H44: =HistoricalFS!H69/HistoricalFS!H$71 -> 0.13545769
B46: =HistoricalFS!B71 -> TOTAL ASSETS | C46: =HistoricalFS!C71/HistoricalFS!C71 -> 1 | D46: =HistoricalFS!D71/HistoricalFS!D71 -> 1 | E46: =HistoricalFS!E71/HistoricalFS!E71 -> 1 | F46: =HistoricalFS!F71/HistoricalFS!F71 -> 1 | G46: =HistoricalFS!G71/HistoricalFS!G71 -> 1 | H46: =HistoricalFS!H71/HistoricalFS!H71 -> 1
B48: =HistoricalFS!B73 -> EQUITY
B49: =HistoricalFS!B74 -> Equity Share Capital | C49: =HistoricalFS!C74/HistoricalFS!C$92 -> 0.013487758 | D49: =HistoricalFS!D74/HistoricalFS!D$92 -> 0.012904857 | E49: =HistoricalFS!E74/HistoricalFS!E$92 -> 0.011485674 | F49: =HistoricalFS!F74/HistoricalFS!F$92 -> 0.010049012 | G49: =HistoricalFS!G74/HistoricalFS!G$92 -> 0.009055888 | H49: =HistoricalFS!H74/HistoricalFS!H$92 -> 0.0076833101
B50: =HistoricalFS!B75 -> Other Equity | C50: =HistoricalFS!C75/HistoricalFS!C$92 -> 0.43958439 | D50: =HistoricalFS!D75/HistoricalFS!D$92 -> 0.50735968 | E50: =HistoricalFS!E75/HistoricalFS!E$92 -> 0.58829924 | F50: =HistoricalFS!F75/HistoricalFS!F$92 -> 0.62370159 | G50: =HistoricalFS!G75/HistoricalFS!G$92 -> 0.64728962 | H50: =HistoricalFS!H75/HistoricalFS!H$92 -> 0.63927049
B51: =HistoricalFS!B77 -> NON-CURRENT LIABILITIES
...

Sheet Rm
B2: Hawkins Cookers Limited
B7: Return on Market
B9: Year | C9: Annual | G9: Median
B10: 2000 | C10: -0.1465 | E10: Average Return | F10: =AVERAGE(C10:C35) -> 0.15149231 | G10: =MEDIAN(C10:C35) -> 0.1135
B11: 2001 | C11: -0.1618 | E11: Dividend Yield | F11: 0.013 | G11: =F11 -> 0.013
B12: 2002 | C12: 0.0325
B13: 2003 | C13: 0.719 | E13: Total Market Return | F13: =SUM(F10:F11) -> 0.16449231 | G13: =SUM(G10:G11) -> 0.1265
B14: 2004 | C14: 0.1068
B15: 2005 | C15: 0.3634
B16: 2006 | C16: 0.3983
B17: 2007 | C17: 0.5477
B18: 2008 | C18: -0.5179
B19: 2009 | C19: 0.7576
B20: 2010 | C20: 0.1795
B21: 2011 | C21: -0.2462
B22: 2012 | C22: 0.277
B23: 2013 | C23: 0.0676
B24: 2014 | C24: 0.3139
B25: 2015 | C25: -0.0406
... B35: 2025 | C35: 0.1051
B36: 2026

Sheet Beta - Regression
B2: Hawkins Cookers Limited
P4: (Values in Rs. Lakhs)
B6: Regression Beta - 2 Years Weekly
B8: Hawkins Cookers Limited - Weekly Returns | F8: Nifty 50 - Weekly Returns | I8: Beta Drifting
B10: Date | C10: Closing Price | D10: Returns | F10: Adj Close | G10: Returns | I10: Levered Raw Beta | J10: =M13 -> 0.18276103 | L10: Beta 1 | M10: =SLOPE(D12:D115,G12:G115) -> 0.18588113
B11: 45516 | C11: 8329.1396 | F11: 24541.15 | I11: Beta Weight | J11: 0.75 | L11: Beta 2 | M11: =_xlfn.COVARIANCE.S(D11:D115,G11:G115)/_xlfn.VAR.S(G11:G115) -> 0.18588113
B12: 45523 | C12: 8430.875 | D12: =C12/C11-1 -> 0.012214389 | F12: 24823.15 | G12: =F12/F11-1 -> 0.011490904
B13: 45530 | C13: 8154.3027 | D13: =C13/C12-1 -> -0.032804693 | F13: 25235.9 | G13: =F13/F12-1 -> 0.016627624 | I13: Market Beta | J13: 1 | L13: Beta 3 | M13: =J40 -> 0.18276103
B14: 45537 | C14: 8318.3145 | D14: =C14/C13-1 -> 0.020113518 | F14: 24852.15 | G14: =F14/F13-1 -> -0.015206511 | I14: Market Beta Weight | J14: =1-J11 -> 0.25
B15: 45544 | C15: 8630.8057 | D15: =C15/C14-1 -> 0.03756665 | F15: 25356.5 | G15: =F15/F14-1 -> 0.020294003
B16: 45551 | C16: 8634.0566 | D16: =C16/C15-1 -> 0.00037667127 | F16: 25790.949 | G16: =F16/F15-1 -> 0.017133643 | I16: Adjusted Beta | J16: =(J10*J11)+(J13*J14) -> 0.38707077
B17: 45558 | C17: 8443.6416 | D17: =C17/C16-1 -> -0.022053948 | F17: 26178.949 | G17: =F17/F16-1 -> 0.015044037
B18: 45565 | C18: 8397.335 | D18: =C18/C17-1 -> -0.0054842025 | F18: 25014.6 | G18: =F18/F17-1 -> -0.04447656 | I18: SUMMARY OUTPUT
B19: 45572 | C19: 8540.0869 | D19: =C19/C18-1 -> 0.016999674 | F19: 24964.25 | G19: =F19/F18-1 -> -0.0020128089
B20: 45579 | C20: 8339.3311 | D20: =C20/C19-1 -> -0.023507473 | F20: 24854.051 | G20: =F20/F19-1 -> -0.0044142812 | I20: Regression Statistics
B21: 45586 | C21: 8203.376 | D21: =C21/C20-1 -> -0.016302876 | F21: 24180.801 | G21: =F21/F20-1 -> -0.02708814 | I21: Multiple R | J21: 0.11617301
B22: 45593 | C22: 8534.9893 | D22: =C22/C21-1 -> 0.040424001 | F22: 24304.35 | G22: =F22/F21-1 -> 0.005109377 | I22: R Square | J22: 0.013496168
B23: 45600 | C23: 8493.3428 | D23: =C23/C22-1 -> -0.0048795005 | F23: 24148.199 | G23: =F23/F22-1 -> -0.006424792 | I23: Adjusted R Square | J23: 0.003728803
B24: 45607 | C24: 8202.9873 | D24: =C24/C23-1 -> -0.034186242 | F24: 23532.699 | G24: =F24/F23-1 -> -0.025488443 | I24: Standard Error | J24: 0.0293215
B25: 45614 | C25: 8267.3008 | D25: =C25/C24-1 -> 0.0078402507 | F25: 23907.25 | G25: =F25/F24-1 -> 0.015916184 | I25: Observations | J25: 103
B26: 45621 | C26: 8263.5146 | D26: =C26/C25-1 -> -0.00045796481 | F26: 24131.1 | G26: =F26/F25-1 -> 0.0093632521
B27: 45628 | C27: 8184.9312 | D27: =C27/C26-1 -> -0.0095096941 | F27: 24677.801 | G27: =F27/F26-1 -> 0.02265546 | I27: ANOVA
B28: 45635 | C28: 8497.6152 | D28: =C28/C27-1 -> 0.038202408 | F28: 24768.301 | G28: =F28/F27-1 -> 0.0036672636 | J28: df | K28: SS
B29: 45642 | C29: 8690.3613 | D29: =C29/C28-1 -> 0.022682375 | F29: 23587.5 | G29: =F29/F28-1 -> -0.047673871 | I29: Regression | J29: 1 | K29: 0.0011879699
B30: 45649 | C30: 8797.0488 | D30: =C30/C29-1 -> 0.012276532 | F30: 23813.4 | G30: =F30/F29-1 -> 0.0095771231 | I30: Residual | J30: 101 | K30: 0.086834786
B31: 45656 | C31: 8774.9639 | D31: =C31/C30-1 -> -0.0025104966 | F31: 24004.75 | G31: =F31/F30-1 -> 0.0080353753 | I31: Total | J31: 102 | K31: 0.088022756
B32: 45663 | C32: 8667.79 | D32: =C32/C31-1 -> -0.012213592 | F32: 23431.5 | G32: =F32/F31-1 -> -0.02388069
B33: 45670 | C33: 8489.1211 | D33: =C33/C32-1 -> -0.020612976 | F33: 23203.199 | G33: =F33/F32-1 -> -0.0097433276 | I33: MS | J33: F | K33: Significance F
B34: 45677 | C34: 8351.0781 | D34: =C34/C33-1 -> -0.016261161 | F34: 23092.199 | G34: =F34/F33-1 -> -0.0047838231 | I34: 0.0011879699 | J34: 1.3817614 | K34: 0.24256491
B35: 45684 | C35: 8119.356 | D35: =C35/C34-1 -> -0.027747575 | F35: 23482.15 | G35: =F35/F34-1 -> 0.016886706 | I35: 0.00085975036
B36: 45691 | C36: 8347.9229 | D36: =C36/C35-1 -> 0.028150865 | F36: 23559.949 | G36: =F36/F35-1 -> 0.0033131049
B37: 45698 | C37: 7434.479 | D37: =C37/C36-1 -> -0.10942169 | F37: 22929.25 | G37: =F37/F36-1 -> -0.026769974
B38: 45705 | C38: 7326.9668 | D38: =C38/C37-1 -> -0.014461297 | F38: 22795.9 | G38: =F38/F37-1 -> -0.0058156987 | J38: Coefficients | K38: Standard Error
B39: 45712 | C39: 7278.5737 | D39: =C39/C38-1 -> -0.0066047886 | F39: 22124.699 | G39: =F39/F38-1 -> -0.029443942 | I39: Intercept | J39: 0.00033399701 | K39: 0.0028891335
B40: 45719 | C40: 7136.4536 | D40: =C40/C39-1 -> -0.01952582 | F40: 22552.5 | G40: =F40/F39-1 -> 0.019335891 | I40: 0.011490904 | J40: 0.18276103 | K40: 0.15547732
B41: 45726 | C41: 7148.103 | D41: =C41/C40-1 -> 0.0016323814 | F41: 22397.199 | G41: =F41/F40-1 -> -0.0068861892
B42: 45733 | C42: 7076.8486 | D42: =C42/C41-1 -> -0.0099682943 | F42: 23350.4 | G42: =F42/F41-1 -> 0.042558945 | I42: t Stat | J42: P-value | K42: Lower 95%
B43: 45740 | C43: 7003.4092 | D43: =C43/C42-1 -> -0.010377423 | F43: 23519.35 | G43: =F43/F42-1 -> 0.0072353885 | I43: 0.11560456 | J43: 0.90819548 | K43: -0.0053972667
B44: 45747 | C44: 7389.6294 | D44: =C44/C43-1 -> 0.055147458 | F44: 22904.449 | G44: =F44/F43-1 -> -0.026144447 | I44: 1.1754835 | J44: 0.24256491 | K44: -0.12566416
B45: 45754 | C45: 7426.2759 | D45: =C45/C44-1 -> 0.0049591776 | F45: 22828.551 | G45: =F45/F44-1 -> -0.0033136984
...

Sheet Beta - Comps
B2: Hawkins Cookers Limited
B6: S.No. | C6: Name | D6: CMP Rs. | E6: Mar Cap Rs.Cr. | F6: Debt Rs.Cr. | G6: Debt / Eq
B7: 1 | C7: Cello World | D7: 377.6 | E7: 8340.62 | F7: 38.11 | G7: 0.01
B8: 2 | C8: Hawkins Cookers | D8: 8351 | E8: 4417.68 | F8: 29.39 | G8: 0.07
B9: 3 | C9: Borosil | D9: 238.55 | E9: 2852.76 | F9: 148.08 | G9: 0.17
B10: 4 | C10: All Time Plastic | D10: 215.54 | E10: 1411.95 | F10: 86.4 | G10: 0.14

Sheet Intrinsic Growth
B2: Hawkins Cookers Limited
B6: Calculation of ROIC | F6: 2021 | G6: 2022 | H6: 2023 | I6: 2024 | J6: 2025 | K6: 2026
B8: Current Operating Assets
B9: Inventories | F9: ='Balance Sheet'!B18 -> 9717.53 | G9: ='Balance Sheet'!C18 -> 17810.07 | H9: ='Balance Sheet'!D18 -> 16956.37 | I9: ='Balance Sheet'!E18 -> 14045.67 | J9: ='Balance Sheet'!F18 -> 15016.63 | K9: ='Balance Sheet'!G18 -> 19296.57
B10: Trade receivables | F10: ='Balance Sheet'!B20 -> 4000.29 | G10: ='Balance Sheet'!C20 -> 5282.95 | H10: ='Balance Sheet'!D20 -> 4741.56 | I10: ='Balance Sheet'!E20 -> 4770.81 | J10: ='Balance Sheet'!F20 -> 6099.88 | K10: ='Balance Sheet'!G20 -> 5760.91
B11: Other current assets | F11: ='Balance Sheet'!B24 -> 2306.33 | G11: ='Balance Sheet'!C24 -> 4618.89 | H11: ='Balance Sheet'!D24 -> 5669.81 | I11: ='Balance Sheet'!E24 -> 4548.34 | J11: ='Balance Sheet'!F24 -> 4959.61 | K11: ='Balance Sheet'!G24 -> 9322.46
B12: Total Current Operating Assets | F12: =SUM(F9:F11) -> 16024.15 | G12: =SUM(G9:G11) -> 27711.91 | H12: =SUM(H9:H11) -> 27367.74 | I12: =SUM(I9:I11) -> 23364.82 | J12: =SUM(J9:J11) -> 26076.12 | K12: =SUM(K9:K11) -> 34379.94
B14: Current Operating Liabilities
B15: Trade payables - To micro & small enterprises | F15: ='Balance Sheet'!B43 -> 774.79 | G15: ='Balance Sheet'!C43 -> 2488.83 | H15: ='Balance Sheet'!D43 -> 1659.36 | I15: ='Balance Sheet'!E43 -> 2383.9 | J15: ='Balance Sheet'!F43 -> 3458.73 | K15: ='Balance Sheet'!G43 -> 3705.41
